[INFO] [1746548301.432400970] [chess_robot_node]: Minimal Chess Robot Node started
[INFO] [1746548301.432868790] [chess_robot_node]: Subscribed to topic: /chess_move
[INFO] [1746548301.433172576] [chess_robot_node]: Node running - waiting for messages
Traceback (most recent call last):
  File "/home/ros/chess_robot_ws/build/chess_robot_simulation/chess_robot_simulation/minimal_node.py", line 27, in main
    rclpy.spin(node)
  File "/opt/ros/humble/local/lib/python3.10/dist-packages/rclpy/__init__.py", line 226, in spin
    executor.spin_once()
  File "/opt/ros/humble/local/lib/python3.10/dist-packages/rclpy/executors.py", line 751, in spin_once
    self._spin_once_impl(timeout_sec)
  File "/opt/ros/humble/local/lib/python3.10/dist-packages/rclpy/executors.py", line 740, in _spin_once_impl
    handler, entity, node = self.wait_for_ready_callbacks(timeout_sec=timeout_sec)
  File "/opt/ros/humble/local/lib/python3.10/dist-packages/rclpy/executors.py", line 723, in wait_for_ready_callbacks
    return next(self._cb_iter)
  File "/opt/ros/humble/local/lib/python3.10/dist-packages/rclpy/executors.py", line 620, in _wait_for_ready_callbacks
    wait_set.wait(timeout_nsec)
KeyboardInterrupt

During handling of the above exception, another exception occurred:

Traceback (most recent call last):
  File "/home/ros/chess_robot_ws/install/chess_robot_simulation/lib/chess_robot_simulation/minimal_node", line 33, in <module>
    sys.exit(load_entry_point('chess-robot-simulation', 'console_scripts', 'minimal_node')())
  File "/home/ros/chess_robot_ws/build/chess_robot_simulation/chess_robot_simulation/minimal_node.py", line 32, in main
    rclpy.shutdown()
  File "/opt/ros/humble/local/lib/python3.10/dist-packages/rclpy/__init__.py", line 130, in shutdown
    _shutdown(context=context)
  File "/opt/ros/humble/local/lib/python3.10/dist-packages/rclpy/utilities.py", line 58, in shutdown
    return context.shutdown()
  File "/opt/ros/humble/local/lib/python3.10/dist-packages/rclpy/context.py", line 102, in shutdown
    self.__context.shutdown()
rclpy._rclpy_pybind11.RCLError: failed to shutdown: rcl_shutdown already called on the given context, at ./src/rcl/init.c:241
